Workbook
Name \0: [1]K!$D$1
Name \B: '[1]PRODUCT COST SHEET - PRIMA'!$B$86
Name \C: [1]SPLITLCP!$BA$1:$BA$3
Name \L: '[1]SS PRIMA PLUS'!$B$109
Name \M: '[1]SS PRIMA HC'!$B$110
Name \P: '[1]PRODUCT & CATEGORY PROFITABILIT'!$B$72
Name \S: [1]K!$E$10
Name \T: [1]K!$K$11
Name \X: '[1]PRODUCT & CATEGORY PROFITABILIT'!$B$74:$B$83
Name \Z: '[1]SS PRIMA UNI'!$B$114
Name _DCC4: [1]DISH!$D$29:$Q$29
Name _dd1: #REF!
Name _dd2: #REF!
Name _DSH1: [1]DISH!$D$11:$Q$14
Name _FCC1: [1]FCC!$D$11:$R$15
Name _FCC3: [1]FCC!$D$25:$R$25
Name _HSC1: [1]HSC!$D$11:$Q$11
Name _HSC4: [1]HSC!$D$29:$R$29
Name _LCP1: [1]SPLITLCP!$C$6:$P$13
Name _LCP2: [1]SPLITLCP!$C$24:$P$31
Name _LCP3: [1]SPLITLCP!$C$43:$P$50
Name _MLT3: [1]NBD!$D$24:$Q$24
Name _MLT4: [1]NBD!$D$31:$Q$31
Name _MLT5: [1]NBD!$D$35:$Q$35
Name _MLT7: [1]NBD!$D$48:$Q$48
Name _NBD1: [1]NBD!$D$11:$R$11
Name _RM426: '[1]SUMMARY REPORTS'!#REF!
Name a: #REF!
Name AA: [1]LCPSECT!$R$17:$R$27
Name aaa: #REF!
Name AB: #REF!
Name AII: #REF!
Name aile: [1]BLENDAX!#REF!
Name APAPCY: #REF!
Name APAPCY_1: #REF!
Name APAPCY_2: #REF!
Name APBYND: #REF!
Name APPREV: #REF!
Name APUNAPCY: #REF!
Name APUNAPCY_1: #REF!
Name APUNAPCY_2: #REF!
Name as: #REF!
Name asdf: #REF!
Name BA_1: '[1]Sched 8'!#REF!
Name BA_2: '[1]Sched 8'!#REF!
Name BA_3: '[1]Sched 8'!#REF!
Name BA_4: '[1]Sched 8'!#REF!
Name BA_5: '[1]Sched 8'!#REF!
Name BA_6: '[1]Sched 8'!#REF!
Name Baby: #REF!
Name baby1: #REF!
Name BB: [1]LCPSECT!$R$17:$R$27
Name bbb: '[1]Sched 8'!#REF!
Name Bev: #REF!
Name BOM_maintained: #REF!
Name Border11: #REF!
Name Border12: #REF!
Name Border13: #REF!
Name Border14: #REF!
Name Border15: #REF!

Sheet CPS
A1: Task | B1: Owner | C1: Time
A2: Health check kick off/Communication email shared | B2: Suz. | C2: 5/11
A3: Finish Health check questions & assessment | B3: Plant/ESS SNP leaders, PSC Owners | C3: 5/11-5/20
A4: Clarification with Plant/PSC owners | B4: Suz./Plant/ESS SNP leaders, PSC owners | C4: 5/21-5/26
A5: Health check result peer reviewed/calibrated and action plan aligned | B5: Suz. /Grace/Zhang Sen | C5: 5/29
A6: Review with Lawrence/Approval in system | B6: Suz./Grace/Lawrence | C6: 6/25
A7: Critical Actions closed | B7: Suz. | C7: 9/30
A8: Major Actions closed | B8: Suz. | C8: 12/30

Sheet 2Y # of  Qs compare
A2: # of Questions Compare
B3: Results | D3: Capability | F3: Processes | H3: Systems | J3: Total
A4: Work Process Assessment | B4: FY2526 | C4: FY2425 | D4: FY2526 | E4: FY2425 | F4: FY2526 | G4: FY2425 | H4: FY2526 | I4: FY2425 | J4: FY2526 | K4: FY2425
A5: Integrated Inventory Management | B5: 2 | C5: 3 | D5: 5 | E5: 6 | F5: 21 | G5: 21 | H5: 8 | I5: 8 | J5: =SUM(B5,D5,F5,H5) -> 36 | K5: =SUM(C5,E5,G5,I5) -> 38
A6: Integrated Service | B6: 1 | C6: 1 | D6: 4 | E6: 4 | F6: 6 | G6: 6 | H6: 1 | I6: 1 | J6: =SUM(B6,D6,F6,H6) -> 12 | K6: =SUM(C6,E6,G6,I6) -> 12
A7: Production Capacity | B7: 2 | C7: 2 | D7: 3 | E7: 3 | F7: 8 | G7: 8 | H7: 2 | I7: 2 | J7: =SUM(B7,D7,F7,H7) -> 15 | K7: =SUM(C7,E7,G7,I7) -> 15
A8: Supply Chain Orchestration | B8: 2 | C8: 2 | D8: 10 | E8: 10 | F8: 31 | G8: 37 | H8: 4 | I8: 4 | J8: =SUM(B8,D8,F8,H8) -> 47 | K8: =SUM(C8,E8,G8,I8) -> 53
B9: =SUM(B5:B8) -> 7 | C9: =SUM(C5:C8) -> 8 | D9: =SUM(D5:D8) -> 22 | E9: =SUM(E5:E8) -> 23 | F9: =SUM(F5:F8) -> 66 | G9: =SUM(G5:G8) -> 72 | H9: =SUM(H5:H8) -> 15 | I9: =SUM(I5:I8) -> 15 | J9: =SUM(B9,D9,F9,H9) -> 110 | K9: =SUM(C9,E9,G9,I9) -> 118
A11: Highlights changes: | B11: 1. Integrated Inv. management, 3 QS reduced, 1 is from result- situational safety tracking cancelled. 2 Qs. cancelled from process- NPI physically exceed 180 days, UPI discussed in D12. QS NPI qs. >90 evaluation and execution being reviewd and quarterly accural qs. split to 2 qs.
B12: 2. Supply chain Orchestration- Cancel 1 QS- POSS, 2 QS-PCL, 2 QS-POW, 1 QS- MSAnT . MSAnT name changes to Manufacturing agility workshop.
A15: FY2425 Result

Sheet FY2526 Questions & Owners-All 
A1: QS | B1: Work Process | C1: No. | D1: Section | E1: Question | F1: Owner | G1: Rational for Scoring | I1: Score | K1: Criteria for Score 0 | L1: Criteria for Score 1 | M1: Criteria for Score 2 | N1: Question can be marked n/a ? | O1: Additional / Reference links | Q1: Action Plan (Mandatory if Score = 0, 1) | R1: Action Criticality (Critical / non-Critical)
A2: 1 | B2: Integrated Inventory Management | C2: 1 | D2: Results | E2: IM- UPI: Total (FP + RPI) % UPI FYTD and Glide path (remainder of the FY) is on or below BU target for the current FY | F2: PSC-Sophia | I2: 0 | K2: No Glidepaths identified and FYTD UPI off track | L2: FYTD UPI off track but glidepath is set to be on track by FY end | M2: UPI Glidepaths set and FYTD UPI on track | N2: FALSE
A3: 2 | B3: Integrated Inventory Management | C3: 2 | D3: Results | E3: IM: Is the evaluation for NPI is performed within 90 days of NPI is identified? Is the action plan for disposal or depletion of NPI physically executed within 90 days after evaluated? | F3: PSC-Yuchen | I3: 0 | K3: NPI is not evaluated fully within 90 days & NPI is not disposed fully within 90 days after evaluation across the RBU. | L3: NPI evaluated fully within 90 Days or NPI disposed fully within 90 days after evaluation across the RBU. | M3: NPI is evaluated fully within 90 days and NPI is disposed fully within 90 days after evaluation across the RBU (Zero overdue NPI evaluation/disposal) | N3: FALSE
A4: 3 | B4: Integrated Inventory Management | C4: 3 | D4: Capability | E4: ITS – FP: ITS Users are able to run scenarios to investigate impacts of supply chain changes or parameter changes into Safety calculations | F4: PSC-Sophia | I4: 0 | K4: missing capability to use what ifs | L4: BU choices done without using what ifs (even though capability exists) | M4: tool if fully leveraged to run scenarios if needed A-ITS - Is the SNP PE capable of running scenarios with minimal or zero help? - Does the scenario outputs require Operational Strategy updates? IBPI: Manual triggering of IBPI engine to reflect changes of masterdata, active participation in tests improving tool | N4: FALSE
A5: 4 | B5: Integrated Inventory Management | C5: 4 | D5: Capability | E5: ITS – FP& RPM : Are all KU or/and system owners qualified within 6 months from starting role? | F5: PSC-Sophia for FP, Jiawen for RPM | I5: 0 | K5: KU not trained and qualified within 6 months | L5: KU qualified but after 6 months in the role [SUC Targets end users as basic / Key users as Intermediate – CSNP/SNP PE is targeted as a KU] | M5: KU trained and qualified within 6 months in the role A-ITS - Is the SNP PE trained and qualified within first 6 months. IBPI& Prima: IBPI KU trained and qualified within first 6 months [SUC Targets end users as basic / Key users as Intermediate – CSNP/SNP PE is targeted as a KU] | N5: FALSE
A6: 5 | B6: Integrated Inventory Management | C6: 5 | D6: Capability | E6: IM- Leadership: Are the Regional inventory solutions Key Users in place and qualified by Regional BPX via the Step Up Card? | F6: PSC-Sophia | I6: 0 | K6: No IM Key User assigned | L6: Inventory key user assigned but not qualified on IM SUC | M6: Inventory key user assigned and qualified with IM SUC | N6: FALSE
A7: 6 | B7: Integrated Inventory Management | C7: 6 | D7: Capability | E7: Cash RCLA: Is there a Loss Analysis Leader identified for the RBU and is qualified on RCLA Step Up Card ? | F7: PSC-Sophia | I7: 0 | K7: No BU Inventory RBU Leader assigned | L7: RBU Inventory Leader assigned but not qualified on Cash RCLA SUC | M7: RBU Inventory Leader assigned and qualified with Cash RCLA SUC | N7: FALSE
A8: 7 | B8: Integrated Inventory Management | C8: 7 | D8: Capability | E8: Process owner defined for every work process and ensures in process/out process measures are tracked & visible (FP ITS, RPM ITS, Cash RCLA & IM) | F8: PSC-Suz. | I8: 0 | K8: No assigned owner | L8: owner assigned but in process/out process measures not tracked | M8: Owner assigned and in process/out process measures are tracked | N8: FALSE
A9: 8 | B9: Integrated Inventory Management | C9: 8 | D9: Processes | E9: ITS – FP: Was standard PACE model and SWP followed throughout the process? | F9: PSC-Sophia | I9: 0 | K9: process not followed (no review process established, no writeback using standard tool, no owner for BU assigned to work on safety) | L9: some of elements of SWP not applied (like owner not in CSNP team, HPPP manually in planning system, and for IBPI IOPT not incorporated) | M9: All elements working which is proved by results A-ITS P - SNP PE A - SCL C - SCL, IOL, CSP, SIP E - SNP PE, SIP IBPI: weekly process, led by CNA team, Review process done (preferably with dynamic review), end users' business knowledge pulled (preferably inside IBPI, but can be offline), safety on aggregate level in line with glidepath, HPPP done inside IBPI, IOPT linkage opened for 90% of matlocs | N9: FALSE
A10: 9 | B10: Integrated Inventory Management | C10: 9 | D10: Processes | E10: ITS FP: Is master data in ITS tool correct and verified on weekly basis, including parameters coming from ITS operating strategy | F10: PSC-Sophia | I10: 0 | K10: no audit | L10: partial, not regular audit | M10: A-ITS: 99% Overall Masterdata compliance score to ensure mandatory elements including examples: APO Layer 1, Network Completeness, and Centerline Compliance review. IBPI: At least mandatory elements are captured in MD checks: production details, IOPT publishing rate, decision where to store safety + all elements required based on ITS strategy | N10: FALSE
A11: 10 | B11: Integrated Inventory Management | C11: 10 | D11: Processes | E11: ITS – FP: Are you reviewing SS from all location/code combinations for all Codes that carrying safety is required (Sites that are stocking locations) | F11: PSC-Sophia | I11: 0 | K11: no review process established | L11: 1/3 of weeks off track (no review) | M11: AITS: Are you utilizing the AITS DMS tracker to document root cause and corrective actions following weekly pit stop review? - DMS Compliance > 90% IBPI: Weekly review, preferably using dynamic review template, review completion >90% | N11: FALSE
A12: 11 | B12: Integrated Inventory Management | C12: 11 | D12: Processes | E12: ITS – FP: Do you have an up to date ITS Operating Strategy as per CBA (including exception handling), to communicate critical inventory target setting parameters supporting different business cases and supply chains. | F12: PSC-Sophia | I12: 0 | K12: no ITS operating strategy | L12: ITS Operating strategy exists but is not up to date or doesn't contain all elements as per CBA | M12: ITS strategy up to date, complete and reviewed regularly as per CBA A-ITS: - Op Strategy includes default (sys) values and exception criteria - Op Strategy is revised and updated quarterly IBPI: ITS strategy part of yearly POW (CBA: vision tab in SWP) & review triggers are to be reviewed at least Quarterly. | N12: FALSE
A13: 12 | B13: Integrated Inventory Management | C13: 12 | D13: Processes | E13: ITS – FP: Were identified safety concerns troubleshot to root cause and addressed in a timely manner? | F13: PSC-Sophia | I13: 0 | K13: no trouble shooting. | L13: no regular process to handle troubleshooting | M13: structural process to handle troubleshooting A-ITS: Is there a weekly (IP @ 100) pit stop review between SNP PE/CSP/IOL ? IBPI: is there proper pit stop structure (IP@100) as platform to raise queries, benchmark and identify opportunities. | N13: FALSE
A14: 13 | B14: Integrated Inventory Management | C14: 13 | D14: Processes | E14: ITS-RPM:Is ITS RPM review conducted on monthly basis for all supply chains ? "Quarterly If aligned" | F14: PSC-Jiawen | I14: 0 | K14: no review process established | L14: Done every 6 months | M14: Done monthly/quarterly based on BU alignment | N14: FALSE
A15: 14 | B15: Integrated Inventory Management | C15: 14 | D15: Processes | E15: ITS-RPM: Is agreed SSS aligned with the supply chain leader before upload? | F15: PSC-Jiawen | I15: 0 | K15: Not aligned | L15: 50% of PRIMA cycles alignment | M15: 100% of PRIMA cycles alignment | N15: FALSE
A16: 15 | B16: Integrated Inventory Management | C16: 15 | D16: Processes | E16: Cash RCLA: Is CASH RCLA SWP being applied in BU and the loss analysis occurred during last 12 months to feed following FY Inventory FIRM ? | F16: PSC-Sophia | I16: 0 | K16: No Cash RCLA SWP applied and no Cash RCLA session occurred in past 12 months to feed following year Inventory FIRM | L16: Cash RCLA SWP applied but no Cash RCLA session occurred in last 12 months or session occurred but not strictly following RCLA approach | M16: Cash RCLA SWP fully applied in BU and Cash RCLA session occurred in past 12 months feeding following FY Inventory FIRM | N16: FALSE
A17: 16 | B17: Integrated Inventory Management | C17: 16 | D17: Processes | E17: Cash RCLA:Is there a regular PDCA cycle that includes the measures & actions tracking ? Are the losses eliminated as per plan ? | F17: PSC-Sophia | I17: 0 | K17: No inventory PDCA in BU | L17: Inventory PDCA in place but not structurally followed, no regular drumbeat | M17: BU Inventory PDCA in place, regular drumbeat in place, actions tracking and losses eliminated as per plan | N17: FALSE
A18: 17 | B18: Integrated Inventory Management | C18: 17 | D18: Processes | E18: Cash RCLA: Are there clear Cash DOH or FCF targets for the next 3 years ahead of RCLA deployed by leadership ? | F18: PSC-Sophia | I18: 0 | K18: No clear target for BU/region deployed | L18: Target deployed but not across the 3 years | M18: Target deployed for the full three years | N18: FALSE
A19: 18 | B19: Integrated Inventory Management | C19: 18 | D19: Processes | E19: Cash RCLA: Are the loss elimination opportunities (TAPA) sufficient to meet the business requirements? | F19: PSC-Sophia | I19: 0 | K19: Action plan opportunities not meeting the business needs (less than 50%) | L19: Action plan opportunities in range of 50% - 100% of business needs (TAPA assumed) | M19: Action plan opportunities exceeding business needs (buffer in TAPA) | N19: FALSE
A20: 19 | B20: Integrated Inventory Management | C20: 19 | D20: Processes | E20: IM- UPI :Is the VS / Category tracking UPI at the bucket level on a weekly basis and communicating internally and to RBU, PSC and SMO leadership on a monthly basis, including leadership reviews? Are the defined and agreed actions sufficient to prevent the inventory gaps from reoccurring? | F20: PSC-Sophia | I20: 0 | K20: NO communication shared internally or externally to ALL UPI buckets | L20: Root causing internally on monthly only for all UPI | M20: Root causing done on weekly basis all UPI and shared with RBU & SMO on monthly basis with action plans sufficient to prevent reoccurring | N20: FALSE
A21: 20 | B21: Integrated Inventory Management | C21: 20 | D21: Processes | E21: IM- UPI: Are NPI codes >90d in Evaluation and Execution being reviewed on a weekly basis and prioritized for action planning. | F21: PSC-Yuchen | I21: 0 | K21: Overdue NPI isn't reviewed | L21: overdue NPI is reviewed on bi-weekly/Monthly | M21: Overdue NPI is reviewed on weekly basis | N21: FALSE
A22: 21 | B22: Integrated Inventory Management | C22: 21 | D22: Processes | E22: IM-UPI: Is NPI accrual done on quarterly basis following the accruals SWP | F22: PSC-Yuchen | I22: 0 | K22: Accrual process isn't done | L22: Accrual process is done but not on quarter basis | M22: Accrual is done on quarter basis following SWP | N22: FALSE
A23: 22 | B23: Integrated Inventory Management | C23: 22 | D23: Processes | E23: IM: Does the VS / Category have scheduled active reviews within the category, RBU and sites to discuss inventory/ UPI issues( Gap versus glidepath) on a weekly basis (weekly Category DDS)? AND on a monthly basis to discuss inv/ UPI issues ( Gap versus glidepath), obstacles and action plans (SNA )? | F23: PSC-Sophia | I23: 0 | K23: NO tracking on Weekly Category DDS and SNA | L23: yes , yet no action plan / root causing shared | M23: yes, root causing and action plan discussed - share documentation | N23: FALSE
A24: 23 | B24: Integrated Inventory Management | C24: 23 | D24: Processes | E24: IM: Are the Daily/Weekly VS (Value Stream), Category, and Demand/Supply DDS covering Inventory/UPI? | F24: PSC-Sophia | I24: 0 | K24: NO inventory discussed in daily basis | L24: NPI is discussed on weekly basis only and not UPI discussed or ME discussion weekly | M24: NPI discussed on daily , UPI discussed in weekly and ME discussed weekly | N24: FALSE
A25: 24 | B25: Integrated Inventory Management | C25: 24 | D25: Processes | E25: IM: Is inventory FF is conducted on monthly basis with clear targets for FP & RPM month closure ? | F25: PSC-Sophia | I25: 0 | K25: No FF conducted | L25: FF done on quarterly basis | M25: FF done on monthly basis with clear monthly targets | N25: FALSE
A26: 25 | B26: Integrated Inventory Management | C26: 25 | D26: Processes | E26: IM- Initiatives: Is the VS / Category executing the PIPO DMS as required for all their initiatives? | F26: PSC-Sophia | I26: 0 | K26: UPI not discussed in initiatives DTM D13 - PIPO codes resulting in UPI | L26: ONLY forecasted RPI hurt is discussed and not current PIPO hurt due to FCST adjustments needed from IOL | M26: UPI behind IOLs id discussed in weekly basis and action plan documented in D13 summary | N26: FALSE
A27: 26 | B27: Integrated Inventory Management | C27: 26 | D27: Processes | E27: IM- Initiative: Has the VS / Category documented Anticipation Inventory assumptions into Operating Strategy and executing it ? | F27: PSC-Sophia | I27: 0 | K27: No anticipation % set in OS | L27: Anticipation strategy set in OS and not followed in execution | M27: Anticipation strategy set in OS and followed in exception | N27: FALSE
A28: 27 | B28: Integrated Inventory Management | C28: 27 | D28: Processes | E28: IM- Initiatives: Does the VS / Category have a robust process to ensure quarterly initiative reviews to reflect as building blocks to the inventory glidepath as part of the Master Plan review and are the building blocks properly communicated and incorporated into the glidepath? | F28: PSC-Sophia | I28: 0 | K28: No quarter review for initiative | L28: Quarter review for initiative and building block set yet not added in glidepaths | M28: Quarter review for initiative done & building block and added in glidepaths | N28: FALSE
... A37: 36 | B37: Integrated Inventory Management | C37: 36 | D37: Systems | E37: IM- UPI: Is the VS / Category executing in depth analysis of top issues utilizing HIT graphs (ISC PBI) at least quarterly for FP and RPI ? | F37: PSC-Sophia | I37: 0 | K37: No hit graphs used | L37: Hit graphs used but only in cash workshops | M37: Hit graphs used on monthly basis - shared documentation , OR no hit graphs used and UPI % is single digit | N37: FALSE
A38: 37 | B38: Integrated Service | C38: 1 | D38: Results | E38: Unanalyzed cuts (Cuts root caused 7.1.1) are < 5% for at least 9 months out of the last 12 months | F38: PSC-Yuchen | I38: 0 | K38: unanalyzed cuts > 5% for last 12 months | L38: unanalyzed cuts < 5% for only 4 months out of last 12 months | M38: unanalyzed cuts <5% for at least 9 out of last 12 months | N38: FALSE
A39: 38 | B39: Integrated Service | C39: 2 | D39: Capability | E39: Are the Regional TOF Key Users in place? | F39: PSC-Cookie | I39: 0 | K39: No key user defined | L39: No key user defined | M39: Yes, Key User in place | N39: FALSE
A40: 39 | B40: Integrated Service | C40: 3 | D40: Capability | E40: Is the TOF Key User knowledge sufficient to help the Organization leverage service tools to drive appropriate action plans and insights? | F40: PSC-Cookie | I40: 0 | K40: Key user isn't supporting the organization | L40: Key user isn't fully knowledgeable about all service Tools/Work processes | M40: Key User has knowledge necessary to support the Organization. | N40: FALSE
A41: 40 | B41: Integrated Service | C41: 4 | D41: Capability | E41: Are the Leaders validating the proper use of Root Causes? And intervening where needed to address and remove the main TOF Root Causes? (For Example: Which system or Work Process failed ? Are Leaders assessing the plausibility of the proposed actions ? Are the defined and agreed actions sufficient to prevent the TOF from reoccurring?) | F41: PSC-Cookie | I41: 0 | K41: Leaders do not engage or evaluate root causes. | L41: Leaders review the root causes at a high level but do not reach for systemic/work process failures and improvements | M41: Leaders regularly review root causes at the true failure level and review action plans for plausibility and completeness. | N41: FALSE
A42: 41 | B42: Integrated Service | C42: 5 | D42: Capability | E42: Process owner defined for every work process and ensures in process/out process measures are tracked & visible (Service Management) | F42: PSC-Suz. | I42: 0 | K42: No assigned owner | L42: owner assigned but in process/out process measures not tracked | M42: Owner assigned and in process/out process measures are tracked | N42: FALSE
A43: 42 | B43: Integrated Service | C43: 6 | D43: Processes | E43: Does our Codes @ risk process happens at least once/week , covers all gaps within Supply Chain Lead time and mitigation plans are in place? | F43: PSC-Yuchen | I43: 0 | K43: No process for Codes @Risk | L43: Process happens but not weekly | M43: process happens at least once/week and mitigation plans being worked to all FPCs on risk | N43: FALSE
A44: 43 | B44: Integrated Service | C44: 7 | D44: Processes | E44: Is critical Code List (FPCs with gaps against orders in coming 2-3 days) being shared & actioned 100% or as per market defined threshold on daily basis? | F44: PSC-Yuchen | I44: 0 | K44: critical code list not shared/actioned | L44: critical code list not shared daily or not 100% actioned/not meeting market defined threshold | M44: critical code list shared daily and 100% actioned/as per Market defined threshold | N44: FALSE
A45: 44 | B45: Integrated Service | C45: 8 | D45: Processes | E45: Does the OU has defined PACE for escalation, escalation threshold agreed and action plans triggered after escalation | F45: PSC-Yuchen | I45: 0 | K45: No PACE/Escalation threshold defined | L45: PACE,Triggers and escalation process defined but not being consistently followed | M45: PACE is defined and action plans are triggered upon escalation | N45: FALSE
A46: 45 | B46: Integrated Service | C46: 9 | D46: Processes | E46: Are the TOF weekly or monthly action plans documented, reviewed, and made available to all parties/posted online with link to document? | F46: PSC-Cookie | I46: 0 | K46: No, all plans were not documented, not reviewed, and/or not uploaded | L46: Monthly plans only are reviewed & documented | M46: Monthly & weekly plans documented, reviewed and uploaded | N46: FALSE
A47: 46 | B47: Integrated Service | C47: 10 | D47: Processes | E47: Are the regional hypercare guidelines and triggers being applied and used consistently? | F47: PSC-Yuchen | I47: 0 | K47: No hypercare guidelines or triggers defined or used | L47: Guidelines and triggers identified but not consistently followed | M47: Guidelines and triggers identified and consistently followed | N47: FALSE
A48: 47 | B48: Integrated Service | C48: 11 | D48: Processes | E48: Are exceptions (restatements) and exclusions to TOF results being done using the PACE model as outlined in the TOF CBA? | F48: PSC-Cookie | I48: 0 | K48: No, the PACE was not followed for any exception or exclusion | L48: PACE is sometimes not followed | M48: PACE is always followed for any exceptions or exclusions | N48: FALSE
...

Sheet FY2425 CSNP HC Question & Owner
A1: Assessment | B1: No | C1: Section | D1: Question | E1: Owner | F1: Rationale/Supporting for Scoring | G1: Score | H1: Criteria for Score 0 | I1: Criteria for Score 1 | J1: Criteria for Score 2 | K1: Link to SWP Benchmarking FY2324 Question & SHA
A2: Integrated Inventory Management | B2: 1 | C2: Results | D2: ITS-FP & RPM: Situational Safety less than or equal 2% average FYTD or as per BU aligned glidepaths ? | E2: PSC-Sophia | H2: Not on target for RPM and FP | I2: Results on track for one ( FP or RPM only ) | J2: Results on track for both FP and RPM | K2: IM
A3: Integrated Inventory Management | B3: 2 | C3: Results | D3: IM- UPI: % UPI and Glide path (remainder of the FY) is on or below BU target for the current FY | E3: PSC-Sophia | H3: No Glidepaths identified and UPI off track | I3: UPI Glidepaths set and UPI on track only for FP or RPM | J3: UPI Glidepaths set and UPI on track for both FP and RPM FYTD | K3: IM
A4: Integrated Inventory Management | B4: 3 | C4: Results | D4: IM: Is the evaluation for NPI is performed within 90 days of NPI is identified? Is the action plan for disposal or depletion of NPI physically executed within 90 days after evaluated? | E4: PSC-Yuchen | H4: NPI is not evaluated fully within 90 days & NPI is not disposed fully within 90 days after evaluation across the RBU. | I4: NPI evaluated fully within 90 Days or NPI disposed fully within 90 days after evaluation across the RBU. | J4: NPI is evaluated fully within 90 days and NPI is disposed fully within 90 days after evaluation across the RBU | K4: IM
A5: Integrated Inventory Management | B5: 4 | C5: Capability | D5: ITS – FP: ITS Users are able to run scenarios to investigate impacts of supply chain changes or parameter changes into Safety calculations | E5: PSC-Ann | H5: missing capability to use what ifs | I5: BU choices done without using what ifs (even though capability exists) | J5: tool what if fully leveraged A-ITS - Is the SNP PE capable of running scenarios with minimal or zero help? - Does the scenario outputs require Operational Strategy updates? IBPI: Manual triggering of IBPI engine to reflect changes of masterdata, active participation in tests improving tool | K5: ITS
A6: Integrated Inventory Management | B6: 5 | C6: Capability | D6: ITS – FP& RPM : Are all KU or/and system owners qualified within 6 months from starting role? | E6: PSC-Ann for FP, Jiawen for RM | H6: KU not trained and qualified within 6 months | I6: KU qualified but after 6 months in the role [SUC Targets end users as basic / Key users as Intermediate – CSNP/SNP PE is targeted as a KU] | J6: KU trained and qualified within 6 months in the role A-ITS - Is the SNP PE trained and qualified within first 6 months. IBPI& Prima: IBPI KU trained and qualified within first 6 months [SUC Targets end users as basic / Key users as Intermediate – CSNP/SNP PE is targeted as a KU] | K6: ITS
A7: Integrated Inventory Management | B7: 6 | C7: Capability | D7: IM- Leadership: Are the Regional inventory solutions Key Users in place and qualified by Regional BPX via the Step Up Card? | E7: PSC-Sophia | H7: No IM Keyuser assigned | I7: Inventory keyuser assigned but not qualified on IM SUC | J7: Inventory keyuser assigned and qualified with IM SUC | K7: IM
A8: Integrated Inventory Management | B8: 7 | C8: Capability | D8: Cash RCLA: Is there a Loss Analysis Leader identified for the RBU and is qualified on RCLA Step Up Card ? | E8: PSC-Sophia | H8: No BU Inventory RBU Leader assigned | I8: RBU Inventory Leader assigned but not qualified on Cash RCLA SUC | J8: RBU Inventory Leader assigned and qualified with Cash RCLA SUC | K8: Cash RCLA
A9: Integrated Inventory Management | B9: 8 | C9: Capability | D9: Process owner defined for every work process and ensures in process/out process measures are tracked & visible | E9: PSC-Yan | H9: No assigned owner | I9: owner assigned but in process/out process measures not tracked | J9: Owner assigned and in process/out process measures are tracked | K9: Capability
A10: Integrated Inventory Management | B10: 9 | C10: Capability | D10: IM - UPI:Is there any physical NPI exceeding 180 days ? Is exception granted from B4 F&A ? | E10: PSC-Yuchen | H10: There's physical NPI >180 and no exception granted | I10: There's physical NPI > 180 and all has exception granted | J10: NO physical NPI more than 180 days | K10: IM
A11: Integrated Inventory Management | B11: 10 | C11: Processes | D11: ITS – FP: Was standard PACE model and SWP followed throughout the process? | E11: PSC-Ann | H11: process not followed (no review process established, no writeback using standard tool, no owner for BU assigned to work on safety) | I11: some of elements of SWP not applied (like owner not in CSNP team, HPPP manually in planning system, and for IBPI IOPT not incorporated) | J11: All elements working which is proved by results A-ITS P - SNP PE A - SCL C - SCL, IOL, CSP, SIP E - SNP PE, SIP IBPI: weekly process, led by CNA team, Review process done (preferably with dynamic review), end users' business knowledge pulled (preferably inside IBPI, but can be offline), safety on aggregate level in line with glidepath, HPPP done inside IBPI, IOPT linkage opened for 90% of matlocs | K11: ITS
A12: Integrated Inventory Management | B12: 11 | C12: Processes | D12: ITS FP: Is master data in ITS tool correct and verified on weekly basis, including parameters coming from ITS operating strategy | E12: PSC-Ann | H12: no audit | I12: partial, not regular audit | J12: weekly auditA-ITS: - 0 APO Layer 1 - 0 Network Completeness errors - 99.8% Overall Centerline IBPI: At least mandatory elements are captured in MD checks: - production details, IOPT publishing rate, decision where to store safety + all elements required based on ITS strategy | K12: ITS
A13: Integrated Inventory Management | B13: 12 | C13: Processes | D13: ITS – FP: Are you reviewing SS from all location/code combinations for all Codes that carrying safety is required (Sites that are stocking locations) | E13: PSC-Ann | H13: no review process established | I13: 1/3 of weeks off track (no review) | J13: results on track full year A-ITS: Weekly review between SNP PE/CSP/IOL IBPI: Weekly review, preferably using dynamic review template, review completion >90% | K13: ITS
... A52: Production Capacity Management | B52: 1 | C52: Results | D52: DFV - Is % difference between BW demand hub and planning system < 2% over 18 Months? | E52: PSC-Ann | H52: DFV process not done/No Tracking measure | I52: Tracking measure but off track one or both metrics: All BU's: Difference of BW Demand Hub and Planning System < 2% over 18 months APO-DRP BU's: All errors are actively being worked weekly to be resolved Non APO-DRP BU's: All code/sites flowing over the next 13 weeks | J52: Tracking and 2 metrics on track: All BU's: Difference of BW Demand Hub and Planning System < 2% over 18 months APO-DRP BU's: All errors are actively being worked weekly to be resolved Non APO-DRP BU's: All code/sites flowing over the next 13 weeks | K52: DFV
A53: Production Capacity Management | B53: 2 | C53: Results | D53: Production C:D compliance above 90% for the next 18 months for all the resources identified as critical | E53: PSC-Initial | G53: 2 | H53: C:D Compliance not measured | I53: C:D compliance measured but < 90% over 18 months | J53: C:D compliance > 90% next 18 months | K53: RCCP
A54: Production Capacity Management | B54: 3 | C54: Capability | D54: Do all Supply Chains have an identified DFV owner in place and fully trained? | E54: PSC-Yan | H54: Does not have all owners identified | I54: Has owners identified but not fully trained | J54: All SC's have owner in place & fully trained: A documented succession plan exists sustaining capability/business continuity. The BU has suffered no losses or erosion or slowdown of results related to staffing or training issues | K54: Capability
A55: Production Capacity Management | B55: 4 | C55: Capability | D55: Do all RCCP families have an identified RCCP owner in place & fully trained? | E55: PSC-Yan | H55: Does not have all owners identified | I55: Has owners identified but not fully trained | J55: All RCCP families have owner in place & fully trained: A documented succession plan exists sustaining capability/business continuity. The BU has suffered no losses or erosion or slowdown of results related to staffing or training issues | K55: Capability
A56: Production Capacity Management | B56: 5 | C56: Capability | D56: Process owner defined for every work process and ensures in process/out process measures are tracked & visible | E56: PSC-Yan | H56: No assigned owner | I56: owner assigned but in process/out process measures not tracked | J56: Owner assigned and in process/out process measures are tracked | K56: Capability
A57: Production Capacity Management | B57: 6 | C57: Processes | D57: DFV SWP being followed according to the PMC | E57: PSC-Ann | H57: Not following SWP | I57: SWP partially followed | J57: SWP fully followed: Checking validation report weekly for differences in the demand flow from Demand Planning system (BW Demand HUB) to Supply Planning systems (e.g. APO DRP, SAP DRP, SAP R3), then working to resolve errors, following a documented process | K57: DFV
A58: Production Capacity Management | B58: 7 | C58: Processes | D58: If you have Global Supply Chains (GSC): Is DFV process in place? | E58: PSC-Ann | H58: No process in place | I58: Partial process in place | J58: Full process in place or don't have GSC (For Global Supply Chains, the CSP in the Destination Region performs DFV) | K58: DFV
A59: Production Capacity Management | B59: 8 | C59: Processes | D59: RCCP SWP being followed according to the RCCP PMC | E59: PSC-Chang | H59: Not following SWP | I59: SWP partially followed | J59: SWP fully followed RCCP's done on all critical Making & Packing constraints All critical constraints from other nodes (Supplier, T&W) are incorporated into Production RCCP plans All Critical constraints have a monthly RCCP process, In monthly buckets and goes out 18 months All Capacity & Demand Below the Line are being added in | K59: RCCP
A60: Production Capacity Management | B60: 9 | C60: Processes | D60: RCCP data inputs are coming from the source system | E60: PSC-Chang | H60: Not using source system as starting point for capacity & demand data | I60: Not fully using source system as starting point for capacity & demand data but using source system to confirm capacity & demand values are in range with the source system | J60: Fully using source system as starting point for capacity & demand data including pulling the data the week after the official BOP Pass weekend Using Production Requirements (From planning system) as the Demand starting point & using Intervals of Available capacity (from planning system) as the Capacity Starting point Capacity Parameters maintained for the RCCP model are based on demonstrated rates, actual staffed operating hours / weeks, plant calendar days. These parameters are documented, and reviewed at least quarterly | K60: RCCP
A61: Production Capacity Management | B61: 10 | C61: Processes | D61: Identification of recommended C:D targets is complete | E61: PSC-Chang | H61: No annual process in place | I61: Annual process in place but not using the CtD target setting tool/aligned OU tool | J61: Annual process in place & using standard tool: Reviewed Annually for all RCCP families. CSNP recommendations are communicated to the BP for input into aligned to CtD target that is included in the Operating Strategy Running new CtD target setting solution (AI Apps) or another aligned standard statistical tools to get recommended CtD for each RCCP family | K61: RCCP
A62: Production Capacity Management | B62: 11 | C62: Processes | D62: Is there a 50/50 & High Side forecast scenario done for all RCCP Families each month? | E62: PSC-Chang | H62: Neither 50/50 or High side RCCP being completed | I62: Only doing 50/50 RCCP: Assumptions are documented regarding Demand / Volume used as inputs for the RCCP volume | J62: Doing both 50/50 & High Side: Assumptions are documented regarding Demand / Volume used as inputs for the RCCP volume Other "what if's" besides High Side are evaluated as needed | K62: RCCP
A63: Production Capacity Management | B63: 12 | C63: Processes | D63: RCCP issues or deviations from Operating strategy are getting discussed & resolved in SNA? | E63: PSC-Chang | H63: RCCP Risks not being discussed in SNA | I63: Capacity related issues or Operating Strategy deviations (service, inventory, etc.) are being discussed in SNA but no clear plan to reduce risks | J63: RCCP risks are talked and clear plan to reduce risks aligned & shared Capacity related issues or Operating Strategy deviations (service, inventory, etc.) are being discussed in SNA including options and an aligned plan to eliminate or resolve capacity risk is completely All parties affected by decision (PSM, Warehouse, Transportation, etc.) are informed Any aligned changes to the plan (Pre-build, sourcing changes, overtime, etc.) should be added to the Planning Systems of Record to let the systems plan accordingly, where applicable | K63: RCCP
A64: Production Capacity Management | B64: 13 | C64: Processes | D64: For Global Supply Chains: Are RCCP’s aggregated across regions for clear view of overall C:D | E64: PSC-Chang | H64: No process in place | I64: Partial process in place for RCCP’s aggregated across regions for clear view of overall C:D | J64: Full process in place (RCCP’s aggregated across regions for clear view of overall C:D) or don't have GSC | K64: RCCP
A65: Production Capacity Management | B65: 14 | C65: Systems | D65: CSNP is using the standard CSP-BW report | E65: PSC-Chang | H65: Not using standard report | I65: No 1 score for this question | J65: Using standard report: APO-DRP BU's: DRP Forecast Flow Validation Report (FFVR) Non APO-DRP BU's: G-CSP-AO-Demand Flow Verification (DFV) report | K65: RCCP
... A85: Supply Chain Orchestration | B85: 19 | C85: Processes | D85: MPS - Is SNP scorecard updated with all MPS measures & correct targets as per IWS Phase and reviewed at least on quarterly basis? | E85: HP/TC/XQ Plant SNP Yantong/Zhelun/Lijun | H85: Scorecard is not always updated with all measures and/or not always reviewed with insufficient gap analysis and action plan | I85: Scorecard is updated with all measures but not always reviewed or with insufficient gap analysis and action plan | J85: Scorecard is updated and reviewed with all measures with gap analysis and action plan | K85: MPS
A86: Supply Chain Orchestration | B86: 20 | C86: Processes | D86: DDS - Are the action plans updated prior the DDS (follow-ups from previous meeting + new known issues added + Actions are updated)? If no current actions because of no issues, check action plan history to confirm action planning is done. | E86: HP/TC/XQ/LY Plant SNP Yantong/Zhelun/Lijun/Xiaoye for D2, PSC Initial/Cookie/Yan for D1/D3/D5/D7 | F86: Action plan has beend documented and tracking completion status. (See screen shot in Column K) | G86: 2 | H86: No action plan exists. | I86: 1 or More Action items exists with due date today or in the past and not resolved yet | J86: All Action Items have dates in the future and are reviewed with the same frequency as the DDS | K86: DDS
A87: Supply Chain Orchestration | B87: 21 | C87: Processes | D87: DDS - Are ALL off-track measures being action planned during the DDS? | E87: HP/TC/XQ/LY Plant SNP Yantong/Zhelun/Lijun/Xiaoye for D2, PSC Initial/Cookie/Yan for D1/D3/D5/D7 | F87: If yesterday service offtrack, we will review 空仓点回补action plan, and focus check production trigger and reflect it into today's production scheduling. If yesterday production have gap will identify mitigation plan, and call out risk if any. | G87: 2 | H87: Off-Track in-process measures not actioned | I87: 50% of off-track in-process measures are actioned | J87: All Off-Track in-process measures are actioned | K87: DDS
A88: Supply Chain Orchestration | B88: 22 | C88: Processes | D88: DDS - Are the mandatory attendees - as per the CBA - the only participants of the meeting? | E88: HP/TC/XQ/LY Plant SNP Yantong/Zhelun/Lijun/Xiaoye for D2, PSC Initial/Cookie/Yan for D1/D3/D5/D7 | F88: In DDS1, we will have plant spoc/MRP/SIP/DRP to review identified triggers and define action plan | G88: 2 | H88: 1 or more Mandatory Attendee are not regularly attending | I88: All mandatory attendees are regularly attending but 1 or More Non-Mandatory Attendee (not regularly) attending the meeting without adding value | J88: Only mandatory attendees are in the meeting, with clear ownership of their respective measures OR 1 or More Non-Mandatory Attendee attending the meeting but clearly adding value. | K88: DDS
A89: Supply Chain Orchestration | B89: 23 | C89: Processes | D89: DDS - Preparation - Are the latest measures actuals completed in the review tool before the meeting? | E89: HP/TC/XQ/LY Plant SNP Yantong/Zhelun/Lijun/Xiaoye for D2, PSC Initial/Cookie/Yan for D1/D3/D5/D7 | F89: we use DDS1 dashboard, so measures will reflect before DDS | G89: 2 | H89: More than 2 measures have no data filled | I89: Maximum of 2 Measures not filled | J89: ALL in-process measures are filled | K89: DDS
A90: Supply Chain Orchestration | B90: 24 | C90: Processes | D90: DDS - Are the Targets & Escalation Triggers documented and known by respective measure owners? Are targets shown in the review tool next to the actual results? | E90: HP/TC/XQ/LY Plant SNP Yantong/Zhelun/Lijun/Xiaoye for D2, PSC Initial/Cookie/Yan for D1/D3/D5/D7 | F90: we use DDS1 dashboard, so target clear show nest to results | G90: 2 | H90: More than 2 Measures have no clear targets or their targets are not shown in the review tool next to the actuals. | I90: Maximum of 2 Measures have no clear targets or their targets are not shown in the review tool next to the actuals. | J90: ALL in-process measures have clear targets and target owners know where the targets are originating from and their targets are not shown in the review tool next to the actuals. | K90: DDS
A91: Supply Chain Orchestration | B91: 25 | C91: Processes | D91: DDS - Does the DDS review ALL and ONLY the standard measures as per the CBA? | E91: HP/TC/XQ/LY Plant SNP Yantong/Zhelun/Lijun/Xiaoye for D2, PSC Initial/Cookie/Yan for D1/D3/D5/D7 | F91: same as above | G91: 2 | H91: Not all Standard Measures as per the CBA are reviewed. | I91: All Standard Measures as per the CBA are reviewed AND DDS discusses NON-Standard measures that have NOT been aligned with the global BU HPN leader AND the HPN RPL | J91: All Standard Measures as per the CBA are reviewed AND (if applicable) DDS discusses NON-Standard measures that have been aligned with the global BU HPN leader AND the HPN RPL - written alignment including rational required. | K91: DDS
A92: Supply Chain Orchestration | B92: 26 | C92: Processes | D92: DDS - Is the DDS frequency as per the CBA [Daily/Weekly/Monthly/Quarterly]? | E92: HP/TC/XQ/LY Plant SNP Yantong/Zhelun/Lijun/Xiaoye for D2, PSC Initial/Cookie/Yan for D1/D3/D5/D7 | F92: DDS1 is daily drumbeat | G92: 2 | H92: DDS Frequency is missed >10% of the times Example: if frequency is Daily, the DDS gets missed 3 Days within 25 WDs in a month | I92: DDS Frequency is missed <10% of the times Example: if frequency is Daily, the DDS gets missed 3 Days within 25 WDs in a month | J92: DDS is happening as per the correct frequency all the time | K92: DDS
A93: Supply Chain Orchestration | B93: 27 | C93: Processes | D93: DDS - Is the DDS taking proper time - No Gap No Yap? | E93: HP/TC/XQ/LY Plant SNP Yantong/Zhelun/Lijun/Xiaoye for D2, PSC Initial/Cookie/Yan for D1/D3/D5/D7 | F93: DDS1 will close within 15~30mins | G93: 2 | H93: DDS timing expands into non-fruitful discussions and doesn't follow the standard time and agenda as per the CBA | I93: DDS timing expands into not-needed discussions but follows the standard time and agenda as per the CBA | J93: DDS time spent ONLY follows the standard time and agenda as per the CBA | K93: DDS
A94: Supply Chain Orchestration | B94: 28 | C94: Processes | D94: POSS - Is POSS available in ePOSS? | E94: HP/TC/XQ Plant SNP Yantong/Zhelun/Lijun | H94: All POSS are not available in E-POSS | I94: 75% of POSS Available in E-POSS | J94: 100% of POSS Available in E-POSS | K94: POSS
A95: Supply Chain Orchestration | B95: 29 | C95: Processes | D95: POSS - POSS is built in line with Site CBN, PSC and BU CBN, OGSM & GTM Ops strategies. Strategies are differentiated via Segmentation and Replenishment Stream (when applicable). Link to E2E Ops strategy available. Site Finance Leader was involved and verified that POSS supports Firm targets delivery. | E95: HP/TC/XQ Plant SNP Yantong/Zhelun/Lijun | H95: Does not include Service-Cash-Cost-Performance Targets | I95: Includes partially Service-Cash-Cost-Performance Targets | J95: Includes all targets Service-Cash-Cost-Performance | K95: POSS
A96: Supply Chain Orchestration | B96: 30 | C96: Processes | D96: POSS - POSS alignment from BU SNO Senior Director happened within the last 12 month at min. | E96: HP/TC/XQ Plant SNP Yantong/Zhelun/Lijun | H96: No POSS updates in any section in the last 12 months | I96: POSS updated but not approved in last 12 months | J96: POSS approved within 12 months | K96: POSS
A97: Supply Chain Orchestration | B97: 31 | C97: Processes | D97: POSS - POSS is known and used by both plant and BU organizations (PSC). (Random check of parameters aligned with plant SPOCs and PSC Planners) | E97: HP/TC/XQ Plant SNP Yantong/Zhelun/Lijun | H97: No audit performed | I97: Audit performed every 12 months | J97: Audit performed every 6 months | K97: POSS
...

Sheet 2Y # of  Qs compare (2)
A2: # of Questions Compare
B3: Results | D3: Capability | F3: Processes | H3: Systems | J3: Total
A4: Work Process Assessment | B4: FY2526 | C4: FY2425 | D4: FY2526 | E4: FY2425 | F4: FY2526 | G4: FY2425 | H4: FY2526 | I4: FY2425 | J4: FY2526 | K4: FY2425
A5: Integrated Inventory Management | B5: 2 | C5: 3 | D5: 5 | E5: 6 | F5: 21 | G5: 21 | H5: 8 | I5: 8 | J5: =SUM(B5,D5,F5,H5) -> 36 | K5: =SUM(C5,E5,G5,I5) -> 38
A6: Integrated Service | B6: 1 | C6: 1 | D6: 4 | E6: 4 | F6: 6 | G6: 6 | H6: 1 | I6: 1 | J6: =SUM(B6,D6,F6,H6) -> 12 | K6: =SUM(C6,E6,G6,I6) -> 12
A7: Production Capacity | B7: 2 | C7: 2 | D7: 3 | E7: 3 | F7: 8 | G7: 8 | H7: 2 | I7: 2 | J7: =SUM(B7,D7,F7,H7) -> 15 | K7: =SUM(C7,E7,G7,I7) -> 15
A8: Supply Chain Orchestration | B8: 2 | C8: 2 | D8: 10 | E8: 10 | F8: 31 | G8: 37 | H8: 4 | I8: 4 | J8: =SUM(B8,D8,F8,H8) -> 47 | K8: =SUM(C8,E8,G8,I8) -> 53
B9: =SUM(B5:B8) -> 7 | C9: =SUM(C5:C8) -> 8 | D9: =SUM(D5:D8) -> 22 | E9: =SUM(E5:E8) -> 23 | F9: =SUM(F5:F8) -> 66 | G9: =SUM(G5:G8) -> 72 | H9: =SUM(H5:H8) -> 15 | I9: =SUM(I5:I8) -> 15 | J9: =SUM(B9,D9,F9,H9) -> 110 | K9: =SUM(C9,E9,G9,I9) -> 118
A11: Highlights changes: | B11: 1. Integrated Inv. management, 3 QS reduced, 1 is from result- situational safety tracking cancelled. 2 Qs. cancelled from process- NPI physically exceed 180 days, UPI discussed in D12. QS NPI qs. >90 evaluation and execution being reviewd and quarterly accural qs. split to 2 qs.
B12: 2. Supply chain Orchestration- Cancel 1 QS- POSS, 2 QS-PCL, 2 QS-POW, 1 QS- MSAnT . MSAnT name changes to Manufacturing agility workshop.

Sheet Integrated Inv. comp.
A1: FY2526 | B1: Section | C1: Question | D1: difference | E1: owner | G1: FY2425 | H1: Section | I1: Question | K1: owner
B2: Results | C2: ITS-FP & RPM: Situational Safety less than or equal 2% average FYTD or as per BU aligned glidepaths ? | D2: 删除 | E2: - | G2: 1 | H2: Results | I2: ITS-FP & RPM: Situational Safety less than or equal 2% average FYTD or as per BU aligned glidepaths ? | J2: FY2425 | K2: PSC-Sophia
A3: 1 | B3: Results | C3: IM- UPI: Total (FP + RPI) % UPI FYTD and Glide path (remainder of the FY) is on or below BU target for the current FY | D3: same | E3: =VLOOKUP(C:C,'FY2526 Questions & Owners-All '!E:F,2,FALSE) -> PSC-Sophia | G3: 2 | H3: Results | I3: IM- UPI: % UPI and Glide path (remainder of the FY) is on or below BU target for the current FY | J3: FY2425 | K3: PSC-Sophia
A4: 2 | B4: Results | C4: IM: Is the evaluation for NPI is performed within 90 days of NPI is identified? Is the action plan for disposal or depletion of NPI physically executed within 90 days after evaluated? | D4: same | E4: =VLOOKUP(C:C,'FY2526 Questions & Owners-All '!E:F,2,FALSE) -> PSC-Yuchen | G4: 3 | H4: Results | I4: IM: Is the evaluation for NPI is performed within 90 days of NPI is identified? Is the action plan for disposal or depletion of NPI physically executed within 90 days after evaluated? | J4: FY2425 | K4: PSC-Yuchen
A5: 3 | B5: Capability | C5: ITS – FP: ITS Users are able to run scenarios to investigate impacts of supply chain changes or parameter changes into Safety calculations | D5: same | E5: =VLOOKUP(C:C,'FY2526 Questions & Owners-All '!E:F,2,FALSE) -> PSC-Sophia | G5: 4 | H5: Capability | I5: ITS – FP: ITS Users are able to run scenarios to investigate impacts of supply chain changes or parameter changes into Safety calculations | J5: FY2425 | K5: PSC-Ann
A6: 4 | B6: Capability | C6: ITS – FP& RPM : Are all KU or/and system owners qualified within 6 months from starting role? | D6: same | E6: =VLOOKUP(C:C,'FY2526 Questions & Owners-All '!E:F,2,FALSE) -> PSC-Sophia for FP, Jiawen for RPM | G6: 5 | H6: Capability | I6: ITS – FP& RPM : Are all KU or/and system owners qualified within 6 months from starting role? | J6: FY2425 | K6: PSC-Ann for FP, Jiawen for RM
A7: 5 | B7: Capability | C7: IM- Leadership: Are the Regional inventory solutions Key Users in place and qualified by Regional BPX via the Step Up Card? | D7: same | E7: =VLOOKUP(C:C,'FY2526 Questions & Owners-All '!E:F,2,FALSE) -> PSC-Sophia | G7: 6 | H7: Capability | I7: IM- Leadership: Are the Regional inventory solutions Key Users in place and qualified by Regional BPX via the Step Up Card? | J7: FY2425 | K7: PSC-Sophia
A8: 6 | B8: Capability | C8: Cash RCLA: Is there a Loss Analysis Leader identified for the RBU and is qualified on RCLA Step Up Card ? | D8: same | E8: =VLOOKUP(C:C,'FY2526 Questions & Owners-All '!E:F,2,FALSE) -> PSC-Sophia | G8: 7 | H8: Capability | I8: Cash RCLA: Is there a Loss Analysis Leader identified for the RBU and is qualified on RCLA Step Up Card ? | J8: FY2425 | K8: PSC-Sophia
A9: 7 | B9: Capability | C9: Process owner defined for every work process and ensures in process/out process measures are tracked & visible (FP ITS, RPM ITS, Cash RCLA & IM) | D9: 改动过 | E9: =VLOOKUP(C:C,'FY2526 Questions & Owners-All '!E:F,2,FALSE) -> PSC-Suz. | G9: 8 | H9: Capability | I9: Process owner defined for every work process and ensures in process/out process measures are tracked & visible | J9: FY2425 | K9: PSC-Yan
B10: Capability | C10: IM - UPI:Is there any physical NPI exceeding 180 days ? Is exception granted from B4 F&A ? | D10: 删除 | E10: - | G10: 9 | H10: Capability | I10: IM - UPI:Is there any physical NPI exceeding 180 days ? Is exception granted from B4 F&A ? | J10: FY2425 | K10: PSC-Yuchen
A11: 8 | B11: Processes | C11: ITS – FP: Was standard PACE model and SWP followed throughout the process? | D11: same | E11: =VLOOKUP(C:C,'FY2526 Questions & Owners-All '!E:F,2,FALSE) -> PSC-Sophia | G11: 10 | H11: Processes | I11: ITS – FP: Was standard PACE model and SWP followed throughout the process? | J11: FY2425 | K11: PSC-Ann
A12: 9 | B12: Processes | C12: ITS FP: Is master data in ITS tool correct and verified on weekly basis, including parameters coming from ITS operating strategy | D12: same | E12: =VLOOKUP(C:C,'FY2526 Questions & Owners-All '!E:F,2,FALSE) -> PSC-Sophia | G12: 11 | H12: Processes | I12: ITS FP: Is master data in ITS tool correct and verified on weekly basis, including parameters coming from ITS operating strategy | J12: FY2425 | K12: PSC-Ann
A13: 10 | B13: Processes | C13: ITS – FP: Are you reviewing SS from all location/code combinations for all Codes that carrying safety is required (Sites that are stocking locations) | D13: same | E13: =VLOOKUP(C:C,'FY2526 Questions & Owners-All '!E:F,2,FALSE) -> PSC-Sophia | G13: 12 | H13: Processes | I13: ITS – FP: Are you reviewing SS from all location/code combinations for all Codes that carrying safety is required (Sites that are stocking locations) | J13: FY2425 | K13: PSC-Ann
A14: 11 | B14: Processes | C14: ITS – FP: Do you have an up to date ITS Operating Strategy as per CBA (including exception handling), to communicate critical inventory target setting parameters supporting different business cases and supply chains. | D14: same | E14: =VLOOKUP(C:C,'FY2526 Questions & Owners-All '!E:F,2,FALSE) -> PSC-Sophia | G14: 13 | H14: Processes | I14: ITS – FP: Do you have an up to date ITS Operating Strategy as per CBA (including exception handling), to communicate critical inventory target setting parameters supporting different business cases and supply chains. | J14: FY2425 | K14: PSC-Ann
A15: 12 | B15: Processes | C15: ITS – FP: Were identified safety concerns troubleshot to root cause and addressed in a timely manner? | D15: same | E15: =VLOOKUP(C:C,'FY2526 Questions & Owners-All '!E:F,2,FALSE) -> PSC-Sophia | G15: 14 | H15: Processes | I15: ITS – FP: Were identified safety concerns troubleshot to root cause and addressed in a timely manner? | J15: FY2425 | K15: PSC-Ann
A16: 13 | B16: Processes | C16: ITS-RPM:Is ITS RPM review conducted on monthly basis for all supply chains ? "Quarterly If aligned" | D16: same | E16: =VLOOKUP(C:C,'FY2526 Questions & Owners-All '!E:F,2,FALSE) -> PSC-Jiawen | G16: 15 | H16: Processes | I16: ITS-RPM:Is ITS RPM review conducted on monthly basis for all supply chains ? "Quarterly If aligned" | J16: FY2425 | K16: PSC-Jiawen
A17: 14 | B17: Processes | C17: ITS-RPM: Is agreed SSS aligned with the supply chain leader before upload? | D17: same | E17: =VLOOKUP(C:C,'FY2526 Questions & Owners-All '!E:F,2,FALSE) -> PSC-Jiawen | G17: 16 | H17: Processes | I17: ITS-RPM: Is agreed SSS aligned with the supply chain leader before upload? | J17: FY2425 | K17: PSC-Jiawen
A18: 15 | B18: Processes | C18: Cash RCLA: Is CASH RCLA SWP being applied in BU and the loss analysis occurred during last 12 months to feed following FY Inventory FIRM ? | D18: same | E18: =VLOOKUP(C:C,'FY2526 Questions & Owners-All '!E:F,2,FALSE) -> PSC-Sophia | G18: 17 | H18: Processes | I18: Cash RCLA: Is CASH RCLA SWP being applied in BU and the loss analysis occurred during last 12 months to feed following FY Inventory FIRM ? | J18: FY2425 | K18: PSC-Sophia
A19: 16 | B19: Processes | C19: Cash RCLA:Is there a regular PDCA cycle that includes the measures & actions tracking ? Are the losses eliminated as per plan ? | D19: same | E19: =VLOOKUP(C:C,'FY2526 Questions & Owners-All '!E:F,2,FALSE) -> PSC-Sophia | G19: 18 | H19: Processes | I19: Cash RCLA:Is there a regular PDCA cycle that includes the measures & actions tracking ? Are the losses eliminated as per plan ? | J19: FY2425 | K19: PSC-Sophia
A20: 17 | B20: Processes | C20: Cash RCLA: Are there clear Cash DOH or FCF targets for the next 3 years ahead of RCLA deployed by leadership ? | D20: 改动过 | E20: =VLOOKUP(C:C,'FY2526 Questions & Owners-All '!E:F,2,FALSE) -> PSC-Sophia | G20: 19 | H20: Processes | I20: Cash RCLA: Are there clear Cash DOH targets for the next 3 years ahead of RCLA deployed by leadership ? | J20: FY2425 | K20: PSC-Sophia
A21: 18 | B21: Processes | C21: Cash RCLA: Are the loss elimination opportunities (TAPA) sufficient to meet the business requirements? | D21: same | E21: =VLOOKUP(C:C,'FY2526 Questions & Owners-All '!E:F,2,FALSE) -> PSC-Sophia | G21: 20 | H21: Processes | I21: Cash RCLA: Are the loss elimination opportunities (TAPA) sufficient to meet the business requirements? | J21: FY2425 | K21: PSC-Sophia
A22: 19 | B22: Processes | C22: IM- UPI :Is the VS / Category tracking UPI at the bucket level on a weekly basis and communicating internally and to RBU, PSC and SMO leadership on a monthly basis, including leadership reviews? Are the defined and agreed actions sufficient to prevent the inventory gaps from reoccurring? | D22: same | E22: PSC-Sophia | G22: 21 | H22: Processes | I22: IM- UPI :Is the VS / Category tracking UPI at the bucket level on a weekly basis and communicating internally and to RBU, PSC and SMO leadership on a monthly basis, including leadership reviews? Are the defined and agreed actions sufficient to prevent the inventory gaps from reoccurring? | J22: FY2425 | K22: PSC-Sophia
A23: 20 | B23: Processes | C23: IM- UPI: Are NPI codes >90d in Evaluation and Execution being reviewed on a weekly basis and prioritized for action planning. | D23: 改动过 | E23: =VLOOKUP(C:C,'FY2526 Questions & Owners-All '!E:F,2,FALSE) -> PSC-Yuchen | G23: 22 | H23: Processes | I23: IM- UPI: Are NPI codes >90d in Decision and Execution "Decision Phase" being reviewed on a weekly basis and prioritized for action planning. Is the NPI Accrual SWP being followed each Quarter? | J23: FY2425 | K23: PSC-Yuchen
A24: 21 | B24: Processes | C24: IM-UPI: Is NPI accrual done on quarterly basis following the accruals SWP | D24: 拆分出来单独一个问题 | E24: =VLOOKUP(C:C,'FY2526 Questions & Owners-All '!E:F,2,FALSE) -> PSC-Yuchen
A25: 22 | B25: Processes | C25: IM: Does the VS / Category have scheduled active reviews within the category, RBU and sites to discuss inventory/ UPI issues( Gap versus glidepath) on a weekly basis (weekly Category DDS)? AND on a monthly basis to discuss inv/ UPI issues ( Gap versus glidepath), obstacles and action plans (SNA )? | D25: same | E25: PSC-Sophia | G25: 23 | H25: Processes | I25: IM-OS: Does the VS / Category have scheduled active reviews within the category, RBU and sites to discuss inventory/ UPI issues( Gap versus glidepath) on a weekly basis (weekly Category DDS)? AND on a monthly basis to discuss inv/ UPI issues ( Gap versus glidepath), obstacles and action plans (SNA )? | J25: FY2425 | K25: PSC-Sophia
A26: 23 | B26: Processes | C26: IM: Are the Daily/Weekly VS (Value Stream), Category, and Demand/Supply DDS covering Inventory/UPI? | D26: 改动过 | E26: =VLOOKUP(C:C,'FY2526 Questions & Owners-All '!E:F,2,FALSE) -> PSC-Sophia | G26: 24 | H26: Processes | I26: IM- RTT: Are the Daily/Weekly VS (Value Stream), Category, and Demand/Supply DDS covering Inventory? | J26: FY2425 | K26: PSC-Sophia
A27: 24 | B27: Processes | C27: IM: Is inventory FF is conducted on monthly basis with clear targets for FP & RPM month closure ? | D27: same | E27: =VLOOKUP(C:C,'FY2526 Questions & Owners-All '!E:F,2,FALSE) -> PSC-Sophia | G27: 25 | H27: Processes | I27: IM- target: Is inventory FF is conducted on monthly basis with clear targets for FP & RPM month closure ? | J27: FY2425 | K27: PSC-Sophia
A28: 25 | B28: Processes | C28: IM- Initiatives: Is the VS / Category executing the PIPO DMS as required for all their initiatives? | D28: same | E28: =VLOOKUP(C:C,'FY2526 Questions & Owners-All '!E:F,2,FALSE) -> PSC-Sophia | G28: 26 | H28: Processes | I28: IM- Initiatives: Is the VS / Category executing the PIPO DMS as required for all their initiatives? | J28: FY2425 | K28: PSC-Sophia
A29: 26 | B29: Processes | C29: IM- Initiative: Has the VS / Category documented Anticipation Inventory assumptions into Operating Strategy and executing it ? | D29: same | E29: =VLOOKUP(C:C,'FY2526 Questions & Owners-All '!E:F,2,FALSE) -> PSC-Sophia | G29: 27 | H29: Processes | I29: IM- Initiative: Has the VS / Category documented Anticipation Inventory assumptions into Operating Strategy and executing it ? | J29: FY2425 | K29: PSC-Sophia
A30: 27 | B30: Processes | C30: IM- Initiatives: Does the VS / Category have a robust process to ensure quarterly initiative reviews to reflect as building blocks to the inventory glidepath as part of the Master Plan review and are the building blocks properly communicated and incorporated into the glidepath? | D30: same | E30: PSC-Sophia | G30: 28 | H30: Processes | I30: IM- Initiatives: Does the VS / Category have a robust process to ensure quarterly initiative reviews to reflect as building blocks to the inventory glidepath as part of the Master Plan review and are the building blocks properly communicated and incorporated into the glidepath? | J30: FY2425 | K30: PSC-Sophia
